{
  "size": [
    5,
    5,
    5
  ],
  "palette": [
    "veinstride:air",
    "veinstride:bricks",
    "veinstride:structure_void",
    "veinstride:oak_door",
    "veinstride:glass",
    "veinstride:torch"
  ],
  "blocks": [
    {
      "pos": [
        0,
        0,
        0
      ],
      "state": 0,
      "stateId": 0
    },
    {
      "pos": [
        1,
        0,
        0
      ],
      "state": 1,
      "stateId": 0
    },
    {
      "pos": [
        2,
        0,
        0
      ],
      "state": 1,
      "stateId": 0
    },
    {
      "pos": [
        3,
        0,
        0
      ],
      "state": 1,
      "stateId": 0
    },
    {
      "pos": [
        4,
        0,
        0
      ],
      "state": 0,
      "stateId": 0
    },
    {
      "pos": [
        0,
        0,
        1
      ],
      "state": 1,
      "stateId": 0
    },
    {
      "pos": [
        1,
        0,
        1
      ],
      "state": 1,
      "stateId": 0
    },
    {
      "pos": [
        2,
        0,
        1
      ],
      "state": 1,
      "stateId": 0
    },
    {
      "pos": [
        3,
        0,
        1
      ],
      "state": 1,
      "stateId": 0
    },
    {
      "pos": [
        4,
        0,
        1
      ],
      "state": 1,
      "stateId": 0
    },
    {
      "pos": [
        0,
        0,
        2
      ],
      "state": 1,
      "stateId": 0
    },
    {
      "pos": [
        1,
        0,
        2
      ],
      "state": 1,
      "stateId": 0
    },
    {
      "pos": [
        2,
        0,
        2
      ],
      "state": 1,
      "stateId": 0
    },
    {
      "pos": [
        3,
        0,
        2
      ],
      "state": 1,
      "stateId": 0
    },
    {
      "pos": [
        4,
        0,
        2
      ],
      "state": 1,
      "stateId": 0
    },
    {
      "pos": [
        0,
        0,
        3
      ],
      "state": 1,
      "stateId": 0
    },
    {
      "pos": [
        1,
        0,
        3
      ],
      "state": 1,
      "stateId": 0
    },
    {
      "pos": [
        2,
        0,
        3
      ],
      "state": 1,
      "stateId": 0
    },
    {
      "pos": [
        3,
        0,
        3
      ],
      "state": 1,
      "stateId": 0
    },
    {
      "pos": [
        4,
        0,
        3
      ],
      "state": 1,
      "stateId": 0
    },
    {
      "pos": [
        0,
        0,
        4
      ],
      "state": 0,
      "stateId": 0
    },
    {
      "pos": [
        1,
        0,
        4
      ],
      "state": 1,
      "stateId": 0
    },
    {
      "pos": [
        2,
        0,
        4
      ],
      "state": 1,
      "stateId": 0
    },
    {
      "pos": [
        3,
        0,
        4
      ],
      "state": 1,
      "stateId": 0
    },
    {
      "pos": [
        4,
        0,
        4
      ],
      "state": 0,
      "stateId": 0
    },
    {
      "pos": [
        0,
        1,
        0
      ],
      "state": 0,
      "stateId": 0
    },
    {
      "pos": [
        1,
        1,
        0
      ],
      "state": 1,
      "stateId": 0
    },
    {
      "pos": [
        2,
        1,
        0
      ],
      "state": 1,
      "stateId": 0
    },
    {
      "pos": [
        3,
        1,
        0
      ],
      "state": 1,
      "stateId": 0
    },
    {
      "pos": [
        4,
        1,
        0
      ],
      "state": 0,
      "stateId": 0
    },
    {
      "pos": [
        0,
        1,
        1
      ],
      "state": 1,
      "stateId": 0
    },
    {
      "pos": [
        1,
        1,
        1
      ],
      "state": 2,
      "stateId": 0
    },
    {
      "pos": [
        2,
        1,
        1
      ],
      "state": 2,
      "stateId": 0
    },
    {
      "pos": [
        3,
        1,
        1
      ],
      "state": 2,
      "stateId": 0
    },
    {
      "pos": [
        4,
        1,
        1
      ],
      "state": 1,
      "stateId": 0
    },
    {
      "pos": [
        0,
        1,
        2
      ],
      "state": 3,
      "stateId": 28
    },
    {
      "pos": [
        1,
        1,
        2
      ],
      "state": 2,
      "stateId": 0
    },
    {
      "pos": [
        2,
        1,
        2
      ],
      "state": 2,
      "stateId": 0
    },
    {
      "pos": [
        3,
        1,
        2
      ],
      "state": 2,
      "stateId": 0
    },
    {
      "pos": [
        4,
        1,
        2
      ],
      "state": 1,
      "stateId": 0
    },
    {
      "pos": [
        0,
        1,
        3
      ],
      "state": 1,
      "stateId": 0
    },
    {
      "pos": [
        1,
        1,
        3
      ],
      "state": 2,
      "stateId": 0
    },
    {
      "pos": [
        2,
        1,
        3
      ],
      "state": 2,
      "stateId": 0
    },
    {
      "pos": [
        3,
        1,
        3
      ],
      "state": 2,
      "stateId": 0
    },
    {
      "pos": [
        4,
        1,
        3
      ],
      "state": 1,
      "stateId": 0
    },
    {
      "pos": [
        0,
        1,
        4
      ],
      "state": 0,
      "stateId": 0
    },
    {
      "pos": [
        1,
        1,
        4
      ],
      "state": 1,
      "stateId": 0
    },
    {
      "pos": [
        2,
        1,
        4
      ],
      "state": 1,
      "stateId": 0
    },
    {
      "pos": [
        3,
        1,
        4
      ],
      "state": 1,
      "stateId": 0
    },
    {
      "pos": [
        4,
        1,
        4
      ],
      "state": 0,
      "stateId": 0
    },
    {
      "pos": [
        0,
        2,
        0
      ],
      "state": 0,
      "stateId": 0
    },
    {
      "pos": [
        1,
        2,
        0
      ],
      "state": 1,
      "stateId": 0
    },
    {
      "pos": [
        2,
        2,
        0
      ],
      "state": 4,
      "stateId": 0
    },
    {
      "pos": [
        3,
        2,
        0
      ],
      "state": 1,
      "stateId": 0
    },
    {
      "pos": [
        4,
        2,
        0
      ],
      "state": 0,
      "stateId": 0
    },
    {
      "pos": [
        0,
        2,
        1
      ],
      "state": 1,
      "stateId": 0
    },
    {
      "pos": [
        1,
        2,
        1
      ],
      "state": 2,
      "stateId": 0
    },
    {
      "pos": [
        2,
        2,
        1
      ],
      "state": 2,
      "stateId": 0
    },
    {
      "pos": [
        3,
        2,
        1
      ],
      "state": 2,
      "stateId": 0
    },
    {
      "pos": [
        4,
        2,
        1
      ],
      "state": 1,
      "stateId": 0
    },
    {
      "pos": [
        0,
        2,
        2
      ],
      "state": 3,
      "stateId": 29
    },
    {
      "pos": [
        1,
        2,
        2
      ],
      "state": 2,
      "stateId": 0
    },
    {
      "pos": [
        2,
        2,
        2
      ],
      "state": 2,
      "stateId": 0
    },
    {
      "pos": [
        3,
        2,
        2
      ],
      "state": 2,
      "stateId": 0
    },
    {
      "pos": [
        4,
        2,
        2
      ],
      "state": 4,
      "stateId": 0
    },
    {
      "pos": [
        0,
        2,
        3
      ],
      "state": 1,
      "stateId": 0
    },
    {
      "pos": [
        1,
        2,
        3
      ],
      "state": 2,
      "stateId": 0
    },
    {
      "pos": [
        2,
        2,
        3
      ],
      "state": 0,
      "stateId": 0
    },
    {
      "pos": [
        3,
        2,
        3
      ],
      "state": 2,
      "stateId": 0
    },
    {
      "pos": [
        4,
        2,
        3
      ],
      "state": 1,
      "stateId": 0
    },
    {
      "pos": [
        0,
        2,
        4
      ],
      "state": 0,
      "stateId": 0
    },
    {
      "pos": [
        1,
        2,
        4
      ],
      "state": 1,
      "stateId": 0
    },
    {
      "pos": [
        2,
        2,
        4
      ],
      "state": 4,
      "stateId": 0
    },
    {
      "pos": [
        3,
        2,
        4
      ],
      "state": 1,
      "stateId": 0
    },
    {
      "pos": [
        4,
        2,
        4
      ],
      "state": 0,
      "stateId": 0
    },
    {
      "pos": [
        0,
        3,
        0
      ],
      "state": 0,
      "stateId": 0
    },
    {
      "pos": [
        1,
        3,
        0
      ],
      "state": 1,
      "stateId": 0
    },
    {
      "pos": [
        2,
        3,
        0
      ],
      "state": 1,
      "stateId": 0
    },
    {
      "pos": [
        3,
        3,
        0
      ],
      "state": 1,
      "stateId": 0
    },
    {
      "pos": [
        4,
        3,
        0
      ],
      "state": 0,
      "stateId": 0
    },
    {
      "pos": [
        0,
        3,
        1
      ],
      "state": 1,
      "stateId": 0
    },
    {
      "pos": [
        1,
        3,
        1
      ],
      "state": 2,
      "stateId": 0
    },
    {
      "pos": [
        2,
        3,
        1
      ],
      "state": 5,
      "stateId": 1
    },
    {
      "pos": [
        3,
        3,
        1
      ],
      "state": 2,
      "stateId": 0
    },
    {
      "pos": [
        4,
        3,
        1
      ],
      "state": 1,
      "stateId": 0
    },
    {
      "pos": [
        0,
        3,
        2
      ],
      "state": 1,
      "stateId": 0
    },
    {
      "pos": [
        1,
        3,
        2
      ],
      "state": 5,
      "stateId": 4
    },
    {
      "pos": [
        2,
        3,
        2
      ],
      "state": 2,
      "stateId": 0
    },
    {
      "pos": [
        3,
        3,
        2
      ],
      "state": 5,
      "stateId": 3
    },
    {
      "pos": [
        4,
        3,
        2
      ],
      "state": 1,
      "stateId": 0
    },
    {
      "pos": [
        0,
        3,
        3
      ],
      "state": 1,
      "stateId": 0
    },
    {
      "pos": [
        1,
        3,
        3
      ],
      "state": 2,
      "stateId": 0
    },
    {
      "pos": [
        2,
        3,
        3
      ],
      "state": 5,
      "stateId": 2
    },
    {
      "pos": [
        3,
        3,
        3
      ],
      "state": 2,
      "stateId": 0
    },
    {
      "pos": [
        4,
        3,
        3
      ],
      "state": 1,
      "stateId": 0
    },
    {
      "pos": [
        0,
        3,
        4
      ],
      "state": 0,
      "stateId": 0
    },
    {
      "pos": [
        1,
        3,
        4
      ],
      "state": 1,
      "stateId": 0
    },
    {
      "pos": [
        2,
        3,
        4
      ],
      "state": 1,
      "stateId": 0
    },
    {
      "pos": [
        3,
        3,
        4
      ],
      "state": 1,
      "stateId": 0
    },
    {
      "pos": [
        4,
        3,
        4
      ],
      "state": 0,
      "stateId": 0
    },
    {
      "pos": [
        0,
        4,
        0
      ],
      "state": 0,
      "stateId": 0
    },
    {
      "pos": [
        1,
        4,
        0
      ],
      "state": 1,
      "stateId": 0
    },
    {
      "pos": [
        2,
        4,
        0
      ],
      "state": 1,
      "stateId": 0
    },
    {
      "pos": [
        3,
        4,
        0
      ],
      "state": 1,
      "stateId": 0
    },
    {
      "pos": [
        4,
        4,
        0
      ],
      "state": 0,
      "stateId": 0
    },
    {
      "pos": [
        0,
        4,
        1
      ],
      "state": 1,
      "stateId": 0
    },
    {
      "pos": [
        1,
        4,
        1
      ],
      "state": 1,
      "stateId": 0
    },
    {
      "pos": [
        2,
        4,
        1
      ],
      "state": 1,
      "stateId": 0
    },
    {
      "pos": [
        3,
        4,
        1
      ],
      "state": 1,
      "stateId": 0
    },
    {
      "pos": [
        4,
        4,
        1
      ],
      "state": 1,
      "stateId": 0
    },
    {
      "pos": [
        0,
        4,
        2
      ],
      "state": 1,
      "stateId": 0
    },
    {
      "pos": [
        1,
        4,
        2
      ],
      "state": 1,
      "stateId": 0
    },
    {
      "pos": [
        2,
        4,
        2
      ],
      "state": 1,
      "stateId": 0
    },
    {
      "pos": [
        3,
        4,
        2
      ],
      "state": 1,
      "stateId": 0
    },
    {
      "pos": [
        4,
        4,
        2
      ],
      "state": 1,
      "stateId": 0
    },
    {
      "pos": [
        0,
        4,
        3
      ],
      "state": 1,
      "stateId": 0
    },
    {
      "pos": [
        1,
        4,
        3
      ],
      "state": 1,
      "stateId": 0
    },
    {
      "pos": [
        2,
        4,
        3
      ],
      "state": 1,
      "stateId": 0
    },
    {
      "pos": [
        3,
        4,
        3
      ],
      "state": 1,
      "stateId": 0
    },
    {
      "pos": [
        4,
        4,
        3
      ],
      "state": 1,
      "stateId": 0
    },
    {
      "pos": [
        0,
        4,
        4
      ],
      "state": 0,
      "stateId": 0
    },
    {
      "pos": [
        1,
        4,
        4
      ],
      "state": 1,
      "stateId": 0
    },
    {
      "pos": [
        2,
        4,
        4
      ],
      "state": 1,
      "stateId": 0
    },
    {
      "pos": [
        3,
        4,
        4
      ],
      "state": 1,
      "stateId": 0
    },
    {
      "pos": [
        4,
        4,
        4
      ],
      "state": 0,
      "stateId": 0
    }
  ]
}