{
  "size": [
    9,
    7,
    9
  ],
  "palette": [
    "veinstride:sandstone",
    "veinstride:sand",
    "veinstride:palm_stairs",
    "veinstride:palm_chest",
    "veinstride:sandstone_slabs",
    "veinstride:sandstone_stairs",
    "veinstride:structure_void",
    "veinstride:sandy_grass",
    "veinstride:palm_trapdoor"
  ],
  "blocks": [
    {
      "pos": [
        0,
        0,
        0
      ],
      "state": 0,
      "stateId": 0
    },
    {
      "pos": [
        1,
        0,
        0
      ],
      "state": 0,
      "stateId": 0
    },
    {
      "pos": [
        2,
        0,
        0
      ],
      "state": 0,
      "stateId": 0
    },
    {
      "pos": [
        3,
        0,
        0
      ],
      "state": 0,
      "stateId": 0
    },
    {
      "pos": [
        4,
        0,
        0
      ],
      "state": 0,
      "stateId": 0
    },
    {
      "pos": [
        5,
        0,
        0
      ],
      "state": 0,
      "stateId": 0
    },
    {
      "pos": [
        6,
        0,
        0
      ],
      "state": 0,
      "stateId": 0
    },
    {
      "pos": [
        7,
        0,
        0
      ],
      "state": 0,
      "stateId": 0
    },
    {
      "pos": [
        8,
        0,
        0
      ],
      "state": 0,
      "stateId": 0
    },
    {
      "pos": [
        0,
        0,
        1
      ],
      "state": 0,
      "stateId": 0
    },
    {
      "pos": [
        1,
        0,
        1
      ],
      "state": 0,
      "stateId": 0
    },
    {
      "pos": [
        2,
        0,
        1
      ],
      "state": 0,
      "stateId": 0
    },
    {
      "pos": [
        3,
        0,
        1
      ],
      "state": 0,
      "stateId": 0
    },
    {
      "pos": [
        4,
        0,
        1
      ],
      "state": 0,
      "stateId": 0
    },
    {
      "pos": [
        5,
        0,
        1
      ],
      "state": 0,
      "stateId": 0
    },
    {
      "pos": [
        6,
        0,
        1
      ],
      "state": 0,
      "stateId": 0
    },
    {
      "pos": [
        7,
        0,
        1
      ],
      "state": 0,
      "stateId": 0
    },
    {
      "pos": [
        8,
        0,
        1
      ],
      "state": 0,
      "stateId": 0
    },
    {
      "pos": [
        0,
        0,
        2
      ],
      "state": 0,
      "stateId": 0
    },
    {
      "pos": [
        1,
        0,
        2
      ],
      "state": 0,
      "stateId": 0
    },
    {
      "pos": [
        2,
        0,
        2
      ],
      "state": 0,
      "stateId": 0
    },
    {
      "pos": [
        3,
        0,
        2
      ],
      "state": 0,
      "stateId": 0
    },
    {
      "pos": [
        4,
        0,
        2
      ],
      "state": 0,
      "stateId": 0
    },
    {
      "pos": [
        5,
        0,
        2
      ],
      "state": 0,
      "stateId": 0
    },
    {
      "pos": [
        6,
        0,
        2
      ],
      "state": 0,
      "stateId": 0
    },
    {
      "pos": [
        7,
        0,
        2
      ],
      "state": 0,
      "stateId": 0
    },
    {
      "pos": [
        8,
        0,
        2
      ],
      "state": 0,
      "stateId": 0
    },
    {
      "pos": [
        0,
        0,
        3
      ],
      "state": 0,
      "stateId": 0
    },
    {
      "pos": [
        1,
        0,
        3
      ],
      "state": 0,
      "stateId": 0
    },
    {
      "pos": [
        2,
        0,
        3
      ],
      "state": 0,
      "stateId": 0
    },
    {
      "pos": [
        3,
        0,
        3
      ],
      "state": 0,
      "stateId": 0
    },
    {
      "pos": [
        4,
        0,
        3
      ],
      "state": 0,
      "stateId": 0
    },
    {
      "pos": [
        5,
        0,
        3
      ],
      "state": 0,
      "stateId": 0
    },
    {
      "pos": [
        6,
        0,
        3
      ],
      "state": 0,
      "stateId": 0
    },
    {
      "pos": [
        7,
        0,
        3
      ],
      "state": 0,
      "stateId": 0
    },
    {
      "pos": [
        8,
        0,
        3
      ],
      "state": 0,
      "stateId": 0
    },
    {
      "pos": [
        0,
        0,
        4
      ],
      "state": 0,
      "stateId": 0
    },
    {
      "pos": [
        1,
        0,
        4
      ],
      "state": 0,
      "stateId": 0
    },
    {
      "pos": [
        2,
        0,
        4
      ],
      "state": 0,
      "stateId": 0
    },
    {
      "pos": [
        3,
        0,
        4
      ],
      "state": 0,
      "stateId": 0
    },
    {
      "pos": [
        4,
        0,
        4
      ],
      "state": 0,
      "stateId": 0
    },
    {
      "pos": [
        5,
        0,
        4
      ],
      "state": 0,
      "stateId": 0
    },
    {
      "pos": [
        6,
        0,
        4
      ],
      "state": 0,
      "stateId": 0
    },
    {
      "pos": [
        7,
        0,
        4
      ],
      "state": 0,
      "stateId": 0
    },
    {
      "pos": [
        8,
        0,
        4
      ],
      "state": 0,
      "stateId": 0
    },
    {
      "pos": [
        0,
        0,
        5
      ],
      "state": 0,
      "stateId": 0
    },
    {
      "pos": [
        1,
        0,
        5
      ],
      "state": 0,
      "stateId": 0
    },
    {
      "pos": [
        2,
        0,
        5
      ],
      "state": 0,
      "stateId": 0
    },
    {
      "pos": [
        3,
        0,
        5
      ],
      "state": 0,
      "stateId": 0
    },
    {
      "pos": [
        4,
        0,
        5
      ],
      "state": 0,
      "stateId": 0
    },
    {
      "pos": [
        5,
        0,
        5
      ],
      "state": 0,
      "stateId": 0
    },
    {
      "pos": [
        6,
        0,
        5
      ],
      "state": 0,
      "stateId": 0
    },
    {
      "pos": [
        7,
        0,
        5
      ],
      "state": 0,
      "stateId": 0
    },
    {
      "pos": [
        8,
        0,
        5
      ],
      "state": 0,
      "stateId": 0
    },
    {
      "pos": [
        0,
        0,
        6
      ],
      "state": 0,
      "stateId": 0
    },
    {
      "pos": [
        1,
        0,
        6
      ],
      "state": 0,
      "stateId": 0
    },
    {
      "pos": [
        2,
        0,
        6
      ],
      "state": 0,
      "stateId": 0
    },
    {
      "pos": [
        3,
        0,
        6
      ],
      "state": 0,
      "stateId": 0
    },
    {
      "pos": [
        4,
        0,
        6
      ],
      "state": 0,
      "stateId": 0
    },
    {
      "pos": [
        5,
        0,
        6
      ],
      "state": 0,
      "stateId": 0
    },
    {
      "pos": [
        6,
        0,
        6
      ],
      "state": 0,
      "stateId": 0
    },
    {
      "pos": [
        7,
        0,
        6
      ],
      "state": 0,
      "stateId": 0
    },
    {
      "pos": [
        8,
        0,
        6
      ],
      "state": 0,
      "stateId": 0
    },
    {
      "pos": [
        0,
        0,
        7
      ],
      "state": 0,
      "stateId": 0
    },
    {
      "pos": [
        1,
        0,
        7
      ],
      "state": 0,
      "stateId": 0
    },
    {
      "pos": [
        2,
        0,
        7
      ],
      "state": 0,
      "stateId": 0
    },
    {
      "pos": [
        3,
        0,
        7
      ],
      "state": 0,
      "stateId": 0
    },
    {
      "pos": [
        4,
        0,
        7
      ],
      "state": 0,
      "stateId": 0
    },
    {
      "pos": [
        5,
        0,
        7
      ],
      "state": 0,
      "stateId": 0
    },
    {
      "pos": [
        6,
        0,
        7
      ],
      "state": 0,
      "stateId": 0
    },
    {
      "pos": [
        7,
        0,
        7
      ],
      "state": 0,
      "stateId": 0
    },
    {
      "pos": [
        8,
        0,
        7
      ],
      "state": 0,
      "stateId": 0
    },
    {
      "pos": [
        0,
        0,
        8
      ],
      "state": 0,
      "stateId": 0
    },
    {
      "pos": [
        1,
        0,
        8
      ],
      "state": 0,
      "stateId": 0
    },
    {
      "pos": [
        2,
        0,
        8
      ],
      "state": 0,
      "stateId": 0
    },
    {
      "pos": [
        3,
        0,
        8
      ],
      "state": 0,
      "stateId": 0
    },
    {
      "pos": [
        4,
        0,
        8
      ],
      "state": 0,
      "stateId": 0
    },
    {
      "pos": [
        5,
        0,
        8
      ],
      "state": 0,
      "stateId": 0
    },
    {
      "pos": [
        6,
        0,
        8
      ],
      "state": 0,
      "stateId": 0
    },
    {
      "pos": [
        7,
        0,
        8
      ],
      "state": 0,
      "stateId": 0
    },
    {
      "pos": [
        8,
        0,
        8
      ],
      "state": 0,
      "stateId": 0
    },
    {
      "pos": [
        0,
        1,
        0
      ],
      "state": 0,
      "stateId": 0
    },
    {
      "pos": [
        1,
        1,
        0
      ],
      "state": 0,
      "stateId": 0
    },
    {
      "pos": [
        2,
        1,
        0
      ],
      "state": 0,
      "stateId": 0
    },
    {
      "pos": [
        3,
        1,
        0
      ],
      "state": 0,
      "stateId": 0
    },
    {
      "pos": [
        4,
        1,
        0
      ],
      "state": 0,
      "stateId": 0
    },
    {
      "pos": [
        5,
        1,
        0
      ],
      "state": 0,
      "stateId": 0
    },
    {
      "pos": [
        6,
        1,
        0
      ],
      "state": 0,
      "stateId": 0
    },
    {
      "pos": [
        7,
        1,
        0
      ],
      "state": 0,
      "stateId": 0
    },
    {
      "pos": [
        8,
        1,
        0
      ],
      "state": 0,
      "stateId": 0
    },
    {
      "pos": [
        0,
        1,
        1
      ],
      "state": 0,
      "stateId": 0
    },
    {
      "pos": [
        1,
        1,
        1
      ],
      "state": 0,
      "stateId": 0
    },
    {
      "pos": [
        2,
        1,
        1
      ],
      "state": 0,
      "stateId": 0
    },
    {
      "pos": [
        3,
        1,
        1
      ],
      "state": 0,
      "stateId": 0
    },
    {
      "pos": [
        4,
        1,
        1
      ],
      "state": 0,
      "stateId": 0
    },
    {
      "pos": [
        5,
        1,
        1
      ],
      "state": 0,
      "stateId": 0
    },
    {
      "pos": [
        6,
        1,
        1
      ],
      "state": 0,
      "stateId": 0
    },
    {
      "pos": [
        7,
        1,
        1
      ],
      "state": 0,
      "stateId": 0
    },
    {
      "pos": [
        8,
        1,
        1
      ],
      "state": 0,
      "stateId": 0
    },
    {
      "pos": [
        0,
        1,
        2
      ],
      "state": 0,
      "stateId": 0
    },
    {
      "pos": [
        1,
        1,
        2
      ],
      "state": 0,
      "stateId": 0
    },
    {
      "pos": [
        2,
        1,
        2
      ],
      "state": 1,
      "stateId": 0
    },
    {
      "pos": [
        3,
        1,
        2
      ],
      "state": 0,
      "stateId": 0
    },
    {
      "pos": [
        4,
        1,
        2
      ],
      "state": 0,
      "stateId": 0
    },
    {
      "pos": [
        5,
        1,
        2
      ],
      "state": 0,
      "stateId": 0
    },
    {
      "pos": [
        6,
        1,
        2
      ],
      "state": 1,
      "stateId": 0
    },
    {
      "pos": [
        7,
        1,
        2
      ],
      "state": 0,
      "stateId": 0
    },
    {
      "pos": [
        8,
        1,
        2
      ],
      "state": 0,
      "stateId": 0
    },
    {
      "pos": [
        0,
        1,
        3
      ],
      "state": 0,
      "stateId": 0
    },
    {
      "pos": [
        1,
        1,
        3
      ],
      "state": 0,
      "stateId": 0
    },
    {
      "pos": [
        2,
        1,
        3
      ],
      "state": 0,
      "stateId": 0
    },
    {
      "pos": [
        3,
        1,
        3
      ],
      "state": 0,
      "stateId": 0
    },
    {
      "pos": [
        4,
        1,
        3
      ],
      "state": 1,
      "stateId": 0
    },
    {
      "pos": [
        5,
        1,
        3
      ],
      "state": 0,
      "stateId": 0
    },
    {
      "pos": [
        6,
        1,
        3
      ],
      "state": 1,
      "stateId": 0
    },
    {
      "pos": [
        7,
        1,
        3
      ],
      "state": 0,
      "stateId": 0
    },
    {
      "pos": [
        8,
        1,
        3
      ],
      "state": 0,
      "stateId": 0
    },
    {
      "pos": [
        0,
        1,
        4
      ],
      "state": 0,
      "stateId": 0
    },
    {
      "pos": [
        1,
        1,
        4
      ],
      "state": 0,
      "stateId": 0
    },
    {
      "pos": [
        2,
        1,
        4
      ],
      "state": 1,
      "stateId": 0
    },
    {
      "pos": [
        3,
        1,
        4
      ],
      "state": 0,
      "stateId": 0
    },
    {
      "pos": [
        4,
        1,
        4
      ],
      "state": 0,
      "stateId": 0
    },
    {
      "pos": [
        5,
        1,
        4
      ],
      "state": 1,
      "stateId": 0
    },
    {
      "pos": [
        6,
        1,
        4
      ],
      "state": 1,
      "stateId": 0
    },
    {
      "pos": [
        7,
        1,
        4
      ],
      "state": 0,
      "stateId": 0
    },
    {
      "pos": [
        8,
        1,
        4
      ],
      "state": 0,
      "stateId": 0
    },
    {
      "pos": [
        0,
        1,
        5
      ],
      "state": 0,
      "stateId": 0
    },
    {
      "pos": [
        1,
        1,
        5
      ],
      "state": 0,
      "stateId": 0
    },
    {
      "pos": [
        2,
        1,
        5
      ],
      "state": 0,
      "stateId": 0
    },
    {
      "pos": [
        3,
        1,
        5
      ],
      "state": 1,
      "stateId": 0
    },
    {
      "pos": [
        4,
        1,
        5
      ],
      "state": 0,
      "stateId": 0
    },
    {
      "pos": [
        5,
        1,
        5
      ],
      "state": 1,
      "stateId": 0
    },
    {
      "pos": [
        6,
        1,
        5
      ],
      "state": 0,
      "stateId": 0
    },
    {
      "pos": [
        7,
        1,
        5
      ],
      "state": 0,
      "stateId": 0
    },
    {
      "pos": [
        8,
        1,
        5
      ],
      "state": 0,
      "stateId": 0
    },
    {
      "pos": [
        0,
        1,
        6
      ],
      "state": 0,
      "stateId": 0
    },
    {
      "pos": [
        1,
        1,
        6
      ],
      "state": 0,
      "stateId": 0
    },
    {
      "pos": [
        2,
        1,
        6
      ],
      "state": 1,
      "stateId": 0
    },
    {
      "pos": [
        3,
        1,
        6
      ],
      "state": 0,
      "stateId": 0
    },
    {
      "pos": [
        4,
        1,
        6
      ],
      "state": 0,
      "stateId": 0
    },
    {
      "pos": [
        5,
        1,
        6
      ],
      "state": 1,
      "stateId": 0
    },
    {
      "pos": [
        6,
        1,
        6
      ],
      "state": 1,
      "stateId": 0
    },
    {
      "pos": [
        7,
        1,
        6
      ],
      "state": 0,
      "stateId": 0
    },
    {
      "pos": [
        8,
        1,
        6
      ],
      "state": 0,
      "stateId": 0
    },
    {
      "pos": [
        0,
        1,
        7
      ],
      "state": 0,
      "stateId": 0
    },
    {
      "pos": [
        1,
        1,
        7
      ],
      "state": 0,
      "stateId": 0
    },
    {
      "pos": [
        2,
        1,
        7
      ],
      "state": 0,
      "stateId": 0
    },
    {
      "pos": [
        3,
        1,
        7
      ],
      "state": 1,
      "stateId": 0
    },
    {
      "pos": [
        4,
        1,
        7
      ],
      "state": 1,
      "stateId": 0
    },
    {
      "pos": [
        5,
        1,
        7
      ],
      "state": 1,
      "stateId": 0
    },
    {
      "pos": [
        6,
        1,
        7
      ],
      "state": 0,
      "stateId": 0
    },
    {
      "pos": [
        7,
        1,
        7
      ],
      "state": 0,
      "stateId": 0
    },
    {
      "pos": [
        8,
        1,
        7
      ],
      "state": 0,
      "stateId": 0
    },
    {
      "pos": [
        0,
        1,
        8
      ],
      "state": 0,
      "stateId": 0
    },
    {
      "pos": [
        1,
        1,
        8
      ],
      "state": 0,
      "stateId": 0
    },
    {
      "pos": [
        2,
        1,
        8
      ],
      "state": 0,
      "stateId": 0
    },
    {
      "pos": [
        3,
        1,
        8
      ],
      "state": 0,
      "stateId": 0
    },
    {
      "pos": [
        4,
        1,
        8
      ],
      "state": 1,
      "stateId": 0
    },
    {
      "pos": [
        5,
        1,
        8
      ],
      "state": 0,
      "stateId": 0
    },
    {
      "pos": [
        6,
        1,
        8
      ],
      "state": 0,
      "stateId": 0
    },
    {
      "pos": [
        7,
        1,
        8
      ],
      "state": 0,
      "stateId": 0
    },
    {
      "pos": [
        8,
        1,
        8
      ],
      "state": 0,
      "stateId": 0
    },
    {
      "pos": [
        1,
        2,
        1
      ],
      "state": 0,
      "stateId": 0
    },
    {
      "pos": [
        2,
        2,
        1
      ],
      "state": 0,
      "stateId": 0
    },
    {
      "pos": [
        3,
        2,
        1
      ],
      "state": 0,
      "stateId": 0
    },
    {
      "pos": [
        4,
        2,
        1
      ],
      "state": 0,
      "stateId": 0
    },
    {
      "pos": [
        5,
        2,
        1
      ],
      "state": 0,
      "stateId": 0
    },
    {
      "pos": [
        6,
        2,
        1
      ],
      "state": 0,
      "stateId": 0
    },
    {
      "pos": [
        7,
        2,
        1
      ],
      "state": 0,
      "stateId": 0
    },
    {
      "pos": [
        1,
        2,
        2
      ],
      "state": 0,
      "stateId": 0
    },
    {
      "pos": [
        3,
        2,
        2
      ],
      "state": 2,
      "stateId": 20
    },
    {
      "pos": [
        4,
        2,
        2
      ],
      "state": 3,
      "stateId": 0,
      "nbt": {
        "x": -13,
        "y": -119,
        "z": 12,
        "Items": []
      }
    },
    {
      "pos": [
        5,
        2,
        2
      ],
      "state": 2,
      "stateId": 30
    },
    {
      "pos": [
        7,
        2,
        2
      ],
      "state": 0,
      "stateId": 0
    },
    {
      "pos": [
        1,
        2,
        3
      ],
      "state": 0,
      "stateId": 0
    },
    {
      "pos": [
        7,
        2,
        3
      ],
      "state": 0,
      "stateId": 0
    },
    {
      "pos": [
        1,
        2,
        4
      ],
      "state": 0,
      "stateId": 0
    },
    {
      "pos": [
        7,
        2,
        4
      ],
      "state": 0,
      "stateId": 0
    },
    {
      "pos": [
        1,
        2,
        5
      ],
      "state": 0,
      "stateId": 0
    },
    {
      "pos": [
        7,
        2,
        5
      ],
      "state": 0,
      "stateId": 0
    },
    {
      "pos": [
        1,
        2,
        6
      ],
      "state": 0,
      "stateId": 0
    },
    {
      "pos": [
        7,
        2,
        6
      ],
      "state": 0,
      "stateId": 0
    },
    {
      "pos": [
        1,
        2,
        7
      ],
      "state": 0,
      "stateId": 0
    },
    {
      "pos": [
        2,
        2,
        7
      ],
      "state": 0,
      "stateId": 0
    },
    {
      "pos": [
        6,
        2,
        7
      ],
      "state": 0,
      "stateId": 0
    },
    {
      "pos": [
        7,
        2,
        7
      ],
      "state": 0,
      "stateId": 0
    },
    {
      "pos": [
        3,
        3,
        8
      ],
      "state": 0,
      "stateId": 0
    },
    {
      "pos": [
        5,
        3,
        8
      ],
      "state": 0,
      "stateId": 0
    },
    {
      "pos": [
        3,
        4,
        6
      ],
      "state": 0,
      "stateId": 0
    },
    {
      "pos": [
        4,
        4,
        6
      ],
      "state": 0,
      "stateId": 0
    },
    {
      "pos": [
        5,
        4,
        6
      ],
      "state": 0,
      "stateId": 0
    },
    {
      "pos": [
        3,
        4,
        7
      ],
      "state": 0,
      "stateId": 0
    },
    {
      "pos": [
        4,
        4,
        7
      ],
      "state": 0,
      "stateId": 0
    },
    {
      "pos": [
        5,
        4,
        7
      ],
      "state": 0,
      "stateId": 0
    },
    {
      "pos": [
        3,
        4,
        8
      ],
      "state": 4,
      "stateId": 0
    },
    {
      "pos": [
        5,
        4,
        8
      ],
      "state": 4,
      "stateId": 0
    },
    {
      "pos": [
        4,
        5,
        4
      ],
      "state": 4,
      "stateId": 1
    },
    {
      "pos": [
        4,
        5,
        6
      ],
      "state": 4,
      "stateId": 0
    },
    {
      "pos": [
        4,
        6,
        4
      ],
      "state": 4,
      "stateId": 0
    },
    {
      "pos": [
        0,
        2,
        0
      ],
      "state": 5,
      "stateId": 14
    },
    {
      "pos": [
        1,
        2,
        0
      ],
      "state": 5,
      "stateId": 10
    },
    {
      "pos": [
        2,
        2,
        0
      ],
      "state": 5,
      "stateId": 10
    },
    {
      "pos": [
        3,
        2,
        0
      ],
      "state": 5,
      "stateId": 10
    },
    {
      "pos": [
        4,
        2,
        0
      ],
      "state": 5,
      "stateId": 10
    },
    {
      "pos": [
        5,
        2,
        0
      ],
      "state": 5,
      "stateId": 10
    },
    {
      "pos": [
        6,
        2,
        0
      ],
      "state": 5,
      "stateId": 10
    },
    {
      "pos": [
        7,
        2,
        0
      ],
      "state": 5,
      "stateId": 10
    },
    {
      "pos": [
        8,
        2,
        0
      ],
      "state": 5,
      "stateId": 34
    },
    {
      "pos": [
        0,
        2,
        1
      ],
      "state": 5,
      "stateId": 20
    },
    {
      "pos": [
        8,
        2,
        1
      ],
      "state": 5,
      "stateId": 30
    },
    {
      "pos": [
        0,
        2,
        2
      ],
      "state": 5,
      "stateId": 20
    },
    {
      "pos": [
        2,
        2,
        2
      ],
      "state": 6,
      "stateId": 0
    },
    {
      "pos": [
        6,
        2,
        2
      ],
      "state": 7,
      "stateId": 0
    },
    {
      "pos": [
        8,
        2,
        2
      ],
      "state": 5,
      "stateId": 30
    },
    {
      "pos": [
        0,
        2,
        3
      ],
      "state": 5,
      "stateId": 20
    },
    {
      "pos": [
        2,
        2,
        3
      ],
      "state": 6,
      "stateId": 0
    },
    {
      "pos": [
        3,
        2,
        3
      ],
      "state": 8,
      "stateId": 12
    },
    {
      "pos": [
        4,
        2,
        3
      ],
      "state": 8,
      "stateId": 12
    },
    {
      "pos": [
        5,
        2,
        3
      ],
      "state": 8,
      "stateId": 12
    },
    {
      "pos": [
        6,
        2,
        3
      ],
      "state": 6,
      "stateId": 0
    },
    {
      "pos": [
        8,
        2,
        3
      ],
      "state": 5,
      "stateId": 30
    },
    {
      "pos": [
        0,
        2,
        4
      ],
      "state": 5,
      "stateId": 20
    },
    {
      "pos": [
        2,
        2,
        4
      ],
      "state": 7,
      "stateId": 0
    },
    {
      "pos": [
        3,
        2,
        4
      ],
      "state": 6,
      "stateId": 0
    },
    {
      "pos": [
        4,
        2,
        4
      ],
      "state": 6,
      "stateId": 0
    },
    {
      "pos": [
        5,
        2,
        4
      ],
      "state": 7,
      "stateId": 0
    },
    {
      "pos": [
        6,
        2,
        4
      ],
      "state": 6,
      "stateId": 0
    },
    {
      "pos": [
        8,
        2,
        4
      ],
      "state": 5,
      "stateId": 30
    },
    {
      "pos": [
        0,
        2,
        5
      ],
      "state": 5,
      "stateId": 20
    },
    {
      "pos": [
        2,
        2,
        5
      ],
      "state": 6,
      "stateId": 0
    },
    {
      "pos": [
        3,
        2,
        5
      ],
      "state": 6,
      "stateId": 0
    },
    {
      "pos": [
        4,
        2,
        5
      ],
      "state": 6,
      "stateId": 0
    },
    {
      "pos": [
        5,
        2,
        5
      ],
      "state": 6,
      "stateId": 0
    },
    {
      "pos": [
        6,
        2,
        5
      ],
      "state": 6,
      "stateId": 0
    },
    {
      "pos": [
        8,
        2,
        5
      ],
      "state": 5,
      "stateId": 30
    },
    {
      "pos": [
        0,
        2,
        6
      ],
      "state": 5,
      "stateId": 20
    },
    {
      "pos": [
        2,
        2,
        6
      ],
      "state": 6,
      "stateId": 0
    },
    {
      "pos": [
        3,
        2,
        6
      ],
      "state": 6,
      "stateId": 0
    },
    {
      "pos": [
        4,
        2,
        6
      ],
      "state": 6,
      "stateId": 0
    },
    {
      "pos": [
        5,
        2,
        6
      ],
      "state": 6,
      "stateId": 0
    },
    {
      "pos": [
        6,
        2,
        6
      ],
      "state": 7,
      "stateId": 0
    },
    {
      "pos": [
        8,
        2,
        6
      ],
      "state": 5,
      "stateId": 30
    },
    {
      "pos": [
        0,
        2,
        7
      ],
      "state": 5,
      "stateId": 20
    },
    {
      "pos": [
        3,
        2,
        7
      ],
      "state": 7,
      "stateId": 0
    },
    {
      "pos": [
        4,
        2,
        7
      ],
      "state": 6,
      "stateId": 0
    },
    {
      "pos": [
        5,
        2,
        7
      ],
      "state": 6,
      "stateId": 0
    },
    {
      "pos": [
        8,
        2,
        7
      ],
      "state": 5,
      "stateId": 30
    },
    {
      "pos": [
        0,
        2,
        8
      ],
      "state": 5,
      "stateId": 24
    },
    {
      "pos": [
        1,
        2,
        8
      ],
      "state": 5,
      "stateId": 0
    },
    {
      "pos": [
        2,
        2,
        8
      ],
      "state": 5,
      "stateId": 0
    },
    {
      "pos": [
        3,
        2,
        8
      ],
      "state": 5,
      "stateId": 22
    },
    {
      "pos": [
        4,
        2,
        8
      ],
      "state": 6,
      "stateId": 0
    },
    {
      "pos": [
        5,
        2,
        8
      ],
      "state": 5,
      "stateId": 31
    },
    {
      "pos": [
        6,
        2,
        8
      ],
      "state": 5,
      "stateId": 0
    },
    {
      "pos": [
        7,
        2,
        8
      ],
      "state": 5,
      "stateId": 0
    },
    {
      "pos": [
        8,
        2,
        8
      ],
      "state": 5,
      "stateId": 33
    },
    {
      "pos": [
        1,
        3,
        1
      ],
      "state": 5,
      "stateId": 14
    },
    {
      "pos": [
        2,
        3,
        1
      ],
      "state": 5,
      "stateId": 10
    },
    {
      "pos": [
        3,
        3,
        1
      ],
      "state": 5,
      "stateId": 10
    },
    {
      "pos": [
        4,
        3,
        1
      ],
      "state": 5,
      "stateId": 10
    },
    {
      "pos": [
        5,
        3,
        1
      ],
      "state": 5,
      "stateId": 10
    },
    {
      "pos": [
        6,
        3,
        1
      ],
      "state": 5,
      "stateId": 10
    },
    {
      "pos": [
        7,
        3,
        1
      ],
      "state": 5,
      "stateId": 34
    },
    {
      "pos": [
        1,
        3,
        2
      ],
      "state": 5,
      "stateId": 20
    },
    {
      "pos": [
        2,
        3,
        2
      ],
      "state": 6,
      "stateId": 0
    },
    {
      "pos": [
        3,
        3,
        2
      ],
      "state": 8,
      "stateId": 0
    },
    {
      "pos": [
        4,
        3,
        2
      ],
      "state": 8,
      "stateId": 0
    },
    {
      "pos": [
        5,
        3,
        2
      ],
      "state": 8,
      "stateId": 0
    },
    {
      "pos": [
        6,
        3,
        2
      ],
      "state": 6,
      "stateId": 0
    },
    {
      "pos": [
        7,
        3,
        2
      ],
      "state": 5,
      "stateId": 30
    },
    {
      "pos": [
        1,
        3,
        3
      ],
      "state": 5,
      "stateId": 20
    },
    {
      "pos": [
        2,
        3,
        3
      ],
      "state": 6,
      "stateId": 0
    },
    {
      "pos": [
        3,
        3,
        3
      ],
      "state": 6,
      "stateId": 0
    },
    {
      "pos": [
        4,
        3,
        3
      ],
      "state": 6,
      "stateId": 0
    },
    {
      "pos": [
        5,
        3,
        3
      ],
      "state": 6,
      "stateId": 0
    },
    {
      "pos": [
        6,
        3,
        3
      ],
      "state": 6,
      "stateId": 0
    },
    {
      "pos": [
        7,
        3,
        3
      ],
      "state": 5,
      "stateId": 30
    },
    {
      "pos": [
        1,
        3,
        4
      ],
      "state": 5,
      "stateId": 20
    },
    {
      "pos": [
        2,
        3,
        4
      ],
      "state": 6,
      "stateId": 0
    },
    {
      "pos": [
        3,
        3,
        4
      ],
      "state": 6,
      "stateId": 0
    },
    {
      "pos": [
        4,
        3,
        4
      ],
      "state": 6,
      "stateId": 0
    },
    {
      "pos": [
        5,
        3,
        4
      ],
      "state": 6,
      "stateId": 0
    },
    {
      "pos": [
        6,
        3,
        4
      ],
      "state": 6,
      "stateId": 0
    },
    {
      "pos": [
        7,
        3,
        4
      ],
      "state": 5,
      "stateId": 30
    },
    {
      "pos": [
        1,
        3,
        5
      ],
      "state": 5,
      "stateId": 20
    },
    {
      "pos": [
        2,
        3,
        5
      ],
      "state": 6,
      "stateId": 0
    },
    {
      "pos": [
        3,
        3,
        5
      ],
      "state": 6,
      "stateId": 0
    },
    {
      "pos": [
        4,
        3,
        5
      ],
      "state": 6,
      "stateId": 0
    },
    {
      "pos": [
        5,
        3,
        5
      ],
      "state": 6,
      "stateId": 0
    },
    {
      "pos": [
        6,
        3,
        5
      ],
      "state": 6,
      "stateId": 0
    },
    {
      "pos": [
        7,
        3,
        5
      ],
      "state": 5,
      "stateId": 30
    },
    {
      "pos": [
        1,
        3,
        6
      ],
      "state": 5,
      "stateId": 20
    },
    {
      "pos": [
        2,
        3,
        6
      ],
      "state": 6,
      "stateId": 0
    },
    {
      "pos": [
        3,
        3,
        6
      ],
      "state": 6,
      "stateId": 0
    },
    {
      "pos": [
        4,
        3,
        6
      ],
      "state": 6,
      "stateId": 0
    },
    {
      "pos": [
        5,
        3,
        6
      ],
      "state": 6,
      "stateId": 0
    },
    {
      "pos": [
        6,
        3,
        6
      ],
      "state": 6,
      "stateId": 0
    },
    {
      "pos": [
        7,
        3,
        6
      ],
      "state": 5,
      "stateId": 30
    },
    {
      "pos": [
        1,
        3,
        7
      ],
      "state": 5,
      "stateId": 3
    },
    {
      "pos": [
        2,
        3,
        7
      ],
      "state": 5,
      "stateId": 22
    },
    {
      "pos": [
        3,
        3,
        7
      ],
      "state": 6,
      "stateId": 0
    },
    {
      "pos": [
        4,
        3,
        7
      ],
      "state": 6,
      "stateId": 0
    },
    {
      "pos": [
        5,
        3,
        7
      ],
      "state": 6,
      "stateId": 0
    },
    {
      "pos": [
        6,
        3,
        7
      ],
      "state": 5,
      "stateId": 31
    },
    {
      "pos": [
        7,
        3,
        7
      ],
      "state": 5,
      "stateId": 4
    },
    {
      "pos": [
        4,
        3,
        8
      ],
      "state": 6,
      "stateId": 0
    },
    {
      "pos": [
        2,
        4,
        2
      ],
      "state": 5,
      "stateId": 23
    },
    {
      "pos": [
        3,
        4,
        2
      ],
      "state": 5,
      "stateId": 10
    },
    {
      "pos": [
        4,
        4,
        2
      ],
      "state": 5,
      "stateId": 10
    },
    {
      "pos": [
        5,
        4,
        2
      ],
      "state": 5,
      "stateId": 10
    },
    {
      "pos": [
        6,
        4,
        2
      ],
      "state": 5,
      "stateId": 13
    },
    {
      "pos": [
        2,
        4,
        3
      ],
      "state": 5,
      "stateId": 20
    },
    {
      "pos": [
        3,
        4,
        3
      ],
      "state": 6,
      "stateId": 0
    },
    {
      "pos": [
        4,
        4,
        3
      ],
      "state": 6,
      "stateId": 0
    },
    {
      "pos": [
        5,
        4,
        3
      ],
      "state": 6,
      "stateId": 0
    },
    {
      "pos": [
        6,
        4,
        3
      ],
      "state": 5,
      "stateId": 30
    },
    {
      "pos": [
        2,
        4,
        4
      ],
      "state": 5,
      "stateId": 20
    },
    {
      "pos": [
        3,
        4,
        4
      ],
      "state": 6,
      "stateId": 0
    },
    {
      "pos": [
        4,
        4,
        4
      ],
      "state": 6,
      "stateId": 0
    },
    {
      "pos": [
        5,
        4,
        4
      ],
      "state": 6,
      "stateId": 0
    },
    {
      "pos": [
        6,
        4,
        4
      ],
      "state": 5,
      "stateId": 30
    },
    {
      "pos": [
        2,
        4,
        5
      ],
      "state": 5,
      "stateId": 20
    },
    {
      "pos": [
        3,
        4,
        5
      ],
      "state": 6,
      "stateId": 0
    },
    {
      "pos": [
        4,
        4,
        5
      ],
      "state": 6,
      "stateId": 0
    },
    {
      "pos": [
        5,
        4,
        5
      ],
      "state": 6,
      "stateId": 0
    },
    {
      "pos": [
        6,
        4,
        5
      ],
      "state": 5,
      "stateId": 30
    },
    {
      "pos": [
        2,
        4,
        6
      ],
      "state": 5,
      "stateId": 3
    },
    {
      "pos": [
        6,
        4,
        6
      ],
      "state": 5,
      "stateId": 4
    },
    {
      "pos": [
        4,
        4,
        8
      ],
      "state": 5,
      "stateId": 0
    },
    {
      "pos": [
        3,
        5,
        3
      ],
      "state": 5,
      "stateId": 14
    },
    {
      "pos": [
        4,
        5,
        3
      ],
      "state": 5,
      "stateId": 10
    },
    {
      "pos": [
        5,
        5,
        3
      ],
      "state": 5,
      "stateId": 13
    },
    {
      "pos": [
        3,
        5,
        4
      ],
      "state": 5,
      "stateId": 20
    },
    {
      "pos": [
        5,
        5,
        4
      ],
      "state": 5,
      "stateId": 30
    },
    {
      "pos": [
        3,
        5,
        5
      ],
      "state": 5,
      "stateId": 24
    },
    {
      "pos": [
        4,
        5,
        5
      ],
      "state": 5,
      "stateId": 0
    },
    {
      "pos": [
        5,
        5,
        5
      ],
      "state": 5,
      "stateId": 33
    }
  ]
}